Workbook
Name Drift.1: 'DATABASE-DRIFT_LATENT_HP_ERROR'!$B$16:$B$23
Name Drift.10: 'DATABASE-DRIFT_LATENT_HP_ERROR'!$B$71:$B$76
Name Drift.2: 'DATABASE-DRIFT_LATENT_HP_ERROR'!$B$24:$B$28
Name Drift.3: 'DATABASE-DRIFT_LATENT_HP_ERROR'!$B$29:$B$34
Name Drift.4: 'DATABASE-DRIFT_LATENT_HP_ERROR'!$B$35:$B$40
Name Drift.5: 'DATABASE-DRIFT_LATENT_HP_ERROR'!$B$41:$B$46
Name Drift.6: 'DATABASE-DRIFT_LATENT_HP_ERROR'!$B$47:$B$52
Name Drift.7: 'DATABASE-DRIFT_LATENT_HP_ERROR'!$B$53:$B$58
Name Drift.8: 'DATABASE-DRIFT_LATENT_HP_ERROR'!$B$59:$B$64
Name Drift.9: 'DATABASE-DRIFT_LATENT_HP_ERROR'!$B$65:$B$70
Name Drift.Code: 'DATABASE-DRIFT_LATENT_HP_ERROR'!$B$4:$B$13
Name DRIFT_LEVEL_1: 'DATABASE-DRIFT_LATENT_HP_ERROR'!$A$4:$A$13
Name Error_Traps.L1: 'DATABASE-DRIFT_LATENT_HP_ERROR'!$K$5:$K$8
Name ErrorTrap.1: 'DATABASE-DRIFT_LATENT_HP_ERROR'!$L$14:$L$20
Name ErrorTrap.2: 'DATABASE-DRIFT_LATENT_HP_ERROR'!$L$21:$L$27
Name ErrorTrap.3: 'DATABASE-DRIFT_LATENT_HP_ERROR'!$L$28:$L$32
Name ErrorTrap.4: 'DATABASE-DRIFT_LATENT_HP_ERROR'!$L$33:$L$37
Name HP.tools: 'DATABASE-DRIFT_LATENT_HP_ERROR'!$F$14:$F$77
Name Latent.1: 'DATABASE-DRIFT_LATENT_HP_ERROR'!$B$89:$B$100
Name Latent.2: 'DATABASE-DRIFT_LATENT_HP_ERROR'!$B$101:$B$111
Name Latent.3: 'DATABASE-DRIFT_LATENT_HP_ERROR'!$B$112:$B$120
Name Latent.4: 'DATABASE-DRIFT_LATENT_HP_ERROR'!$B$121:$B$129
Name Latent.5: 'DATABASE-DRIFT_LATENT_HP_ERROR'!$B$130:$B$137
Name Latent_Level.1: 'DATABASE-DRIFT_LATENT_HP_ERROR'!$A$81:$A$85
Name VV_Protocols: 'DATABASE-DRIFT_LATENT_HP_ERROR'!$A$143:$A$155

Sheet INPUT-SIF_Questions
A1: Obs_ID | B1: Observation_Sequence | C1: PSIE_Eligible | D1: Baseline_Obs_ID | E1: Improvement_ID | F1: Observation_Status | G1: Active_Observation | H1: Protocols_code | I1: Protocols_name | J1: Question_Ref | K1: CCVC_ID | L1: Observation_Question | M1: YES | N1: NO | O1: NA | P1: Comments | Q1: SIF_Exposure | R1: Critical_Safeguard | S1: Observation_Date | T1: Year | U1: Quarter | V1: Zona | W1: Site | X1: Area_Equipment | Y1: Activity | Z1: Company | AA1: Observer_1 | AB1: Observer_2 | AC1: Observer_3 | AD1: SC_name | AE1: AA_name | AF1: PA_name
A2: OBS-001 | B2: 1 | C2: N | F2: =IF(A2="","",IF(B2=1,"Baseline",IF(C2="Y","Reverification","Follow-up"))) -> Baseline | G2: =IF(A2="","",IF(COUNTIFS($V$2:$V$300,V2,$H$2:$H$300,H2,$B$2:$B$300,">"&B2)=0,"Y","N")) -> Y | H2: WAH | I2: =IFERROR(VLOOKUP(H2,'DATABASE-DRIFT_LATENT_HP_ERROR'!$A$143:$B$160,2,FALSE()),"") -> Work at Height | J2: A | K2: CLSR07-A | L2: Pemahaman fall restraint vs fall arrest | N2: 1 | P2: Crew belum memahami hierarchy of control | Q2: Fall from height | R2: Fall Protection | S2: 46156 | T2: =IF(S2="","",YEAR(S2)) -> 2026 | U2: =IF(S2="","","TW "&CHOOSE(ROUNDUP(MONTH(S2)/3,0),"I","II","III","IV")) -> TW II | V2: 13 | W2: CPP MATINDOK | X2: GTG Area | Y2: Scaffolding Dismantling | Z2: PT Petro Teknik Konstruksi | AA2: Iman Sudirman | AB2: Endong Darwilisan Yahya | AC2: Wayan Edi Wijaya
A3: OBS-001 | B3: 1 | C3: N | F3: =IF(A3="","",IF(B3=1,"Baseline",IF(C3="Y","Reverification","Follow-up"))) -> Baseline | G3: =IF(A3="","",IF(COUNTIFS($V$2:$V$300,V3,$H$2:$H$300,H3,$B$2:$B$300,">"&B3)=0,"Y","N")) -> Y | H3: WAH | I3: =IFERROR(VLOOKUP(H3,'DATABASE-DRIFT_LATENT_HP_ERROR'!$A$143:$B$160,2,FALSE()),"") -> Work at Height | J3: B | K3: CLSR07-B | L3: Pemahaman restraint vs arrest lanyard | N3: 1 | P3: Perbedaan fungsi belum dipahami | Q3: Fall from height | R3: Correct Equipment | S3: 46156 | T3: =IF(S3="","",YEAR(S3)) -> 2026 | U3: =IF(S3="","","TW "&CHOOSE(ROUNDUP(MONTH(S3)/3,0),"I","II","III","IV")) -> TW II | V3: 13 | W3: CPP MATINDOK | X3: GTG Area | Y3: Scaffolding Dismantling | Z3: PT Petro Teknik Konstruksi | AA3: Iman Sudirman | AB3: Endong Darwilisan Yahya | AC3: Wayan Edi Wijaya
A4: OBS-001 | B4: 1 | C4: N | F4: =IF(A4="","",IF(B4=1,"Baseline",IF(C4="Y","Reverification","Follow-up"))) -> Baseline | G4: =IF(A4="","",IF(COUNTIFS($V$2:$V$300,V4,$H$2:$H$300,H4,$B$2:$B$300,">"&B4)=0,"Y","N")) -> Y | H4: WAH | I4: =IFERROR(VLOOKUP(H4,'DATABASE-DRIFT_LATENT_HP_ERROR'!$A$143:$B$160,2,FALSE()),"") -> Work at Height | J4: C | K4: CLSR07-C | L4: Free fall distance calculation | N4: 1 | P4: Tidak ada free fall calculation | Q4: Fatality | R4: Engineering Safeguard | S4: 46156 | T4: =IF(S4="","",YEAR(S4)) -> 2026 | U4: =IF(S4="","","TW "&CHOOSE(ROUNDUP(MONTH(S4)/3,0),"I","II","III","IV")) -> TW II | V4: 13 | W4: CPP MATINDOK | X4: GTG Area | Y4: Scaffolding Dismantling | Z4: PT Petro Teknik Konstruksi | AA4: Iman Sudirman | AB4: Endong Darwilisan Yahya | AC4: Wayan Edi Wijaya
A5: OBS-001 | B5: 1 | C5: N | F5: =IF(A5="","",IF(B5=1,"Baseline",IF(C5="Y","Reverification","Follow-up"))) -> Baseline | G5: =IF(A5="","",IF(COUNTIFS($V$2:$V$300,V5,$H$2:$H$300,H5,$B$2:$B$300,">"&B5)=0,"Y","N")) -> Y | H5: WAH | I5: =IFERROR(VLOOKUP(H5,'DATABASE-DRIFT_LATENT_HP_ERROR'!$A$143:$B$160,2,FALSE()),"") -> Work at Height | J5: D | K5: CLSR07-D | L5: Anchorage point verification | M5: 1 | P5: Anchorage cukup kuat | Q5: Fall Protection | R5: Anchorage Integrity | S5: 46156 | T5: =IF(S5="","",YEAR(S5)) -> 2026 | U5: =IF(S5="","","TW "&CHOOSE(ROUNDUP(MONTH(S5)/3,0),"I","II","III","IV")) -> TW II | V5: 13 | W5: CPP MATINDOK | X5: GTG Area | Y5: Scaffolding Dismantling | Z5: PT Petro Teknik Konstruksi | AA5: Iman Sudirman | AB5: Endong Darwilisan Yahya | AC5: Wayan Edi Wijaya
A6: OBS-001 | B6: 1 | C6: N | F6: =IF(A6="","",IF(B6=1,"Baseline",IF(C6="Y","Reverification","Follow-up"))) -> Baseline | G6: =IF(A6="","",IF(COUNTIFS($V$2:$V$300,V6,$H$2:$H$300,H6,$B$2:$B$300,">"&B6)=0,"Y","N")) -> Y | H6: WAH | I6: =IFERROR(VLOOKUP(H6,'DATABASE-DRIFT_LATENT_HP_ERROR'!$A$143:$B$160,2,FALSE()),"") -> Work at Height | J6: E | K6: CLSR07-E | L6: 100% tie off | M6: 1 | P6: Crew melakukan 100% tie off | Q6: Fall Protection | R6: Continuous Connection | S6: 46156 | T6: =IF(S6="","",YEAR(S6)) -> 2026 | U6: =IF(S6="","","TW "&CHOOSE(ROUNDUP(MONTH(S6)/3,0),"I","II","III","IV")) -> TW II | V6: 13 | W6: CPP MATINDOK | X6: GTG Area | Y6: Scaffolding Dismantling | Z6: PT Petro Teknik Konstruksi | AA6: Iman Sudirman | AB6: Endong Darwilisan Yahya | AC6: Wayan Edi Wijaya
A7: OBS-001 | B7: 1 | C7: N | F7: =IF(A7="","",IF(B7=1,"Baseline",IF(C7="Y","Reverification","Follow-up"))) -> Baseline | G7: =IF(A7="","",IF(COUNTIFS($V$2:$V$300,V7,$H$2:$H$300,H7,$B$2:$B$300,">"&B7)=0,"Y","N")) -> Y | H7: WAH | I7: =IFERROR(VLOOKUP(H7,'DATABASE-DRIFT_LATENT_HP_ERROR'!$A$143:$B$160,2,FALSE()),"") -> Work at Height | J7: F | K7: CLSR07-F | L7: Swing fall prevention | N7: 1 | P7: Swing fall belum diperhitungkan | Q7: Secondary impact | R7: Safe Anchorage | S7: 46156 | T7: =IF(S7="","",YEAR(S7)) -> 2026 | U7: =IF(S7="","","TW "&CHOOSE(ROUNDUP(MONTH(S7)/3,0),"I","II","III","IV")) -> TW II | V7: 13 | W7: CPP MATINDOK | X7: GTG Area | Y7: Scaffolding Dismantling | Z7: PT Petro Teknik Konstruksi | AA7: Iman Sudirman | AB7: Endong Darwilisan Yahya | AC7: Wayan Edi Wijaya
A8: OBS-001 | B8: 1 | C8: N | F8: =IF(A8="","",IF(B8=1,"Baseline",IF(C8="Y","Reverification","Follow-up"))) -> Baseline | G8: =IF(A8="","",IF(COUNTIFS($V$2:$V$300,V8,$H$2:$H$300,H8,$B$2:$B$300,">"&B8)=0,"Y","N")) -> Y | H8: WAH | I8: =IFERROR(VLOOKUP(H8,'DATABASE-DRIFT_LATENT_HP_ERROR'!$A$143:$B$160,2,FALSE()),"") -> Work at Height | J8: G | K8: CLSR07-G | L8: Inspection equipment | M8: 1 | P8: Harness dan lanyard diperiksa | Q8: Equipment Integrity | R8: Equipment Inspection | S8: 46156 | T8: =IF(S8="","",YEAR(S8)) -> 2026 | U8: =IF(S8="","","TW "&CHOOSE(ROUNDUP(MONTH(S8)/3,0),"I","II","III","IV")) -> TW II | V8: 13 | W8: CPP MATINDOK | X8: GTG Area | Y8: Scaffolding Dismantling | Z8: PT Petro Teknik Konstruksi | AA8: Iman Sudirman | AB8: Endong Darwilisan Yahya | AC8: Wayan Edi Wijaya
A9: OBS-001 | B9: 1 | C9: N | F9: =IF(A9="","",IF(B9=1,"Baseline",IF(C9="Y","Reverification","Follow-up"))) -> Baseline | G9: =IF(A9="","",IF(COUNTIFS($V$2:$V$300,V9,$H$2:$H$300,H9,$B$2:$B$300,">"&B9)=0,"Y","N")) -> Y | H9: WAH | I9: =IFERROR(VLOOKUP(H9,'DATABASE-DRIFT_LATENT_HP_ERROR'!$A$143:$B$160,2,FALSE()),"") -> Work at Height | J9: H | K9: CLSR07-H | L9: Correct harness use | M9: 1 | P9: Harness digunakan dengan benar | Q9: Fall Protection | R9: Proper Harness Use | S9: 46156 | T9: =IF(S9="","",YEAR(S9)) -> 2026 | U9: =IF(S9="","","TW "&CHOOSE(ROUNDUP(MONTH(S9)/3,0),"I","II","III","IV")) -> TW II | V9: 13 | W9: CPP MATINDOK | X9: GTG Area | Y9: Scaffolding Dismantling | Z9: PT Petro Teknik Konstruksi | AA9: Iman Sudirman | AB9: Endong Darwilisan Yahya | AC9: Wayan Edi Wijaya
A10: OBS-001 | B10: 1 | C10: N | F10: =IF(A10="","",IF(B10=1,"Baseline",IF(C10="Y","Reverification","Follow-up"))) -> Baseline | G10: =IF(A10="","",IF(COUNTIFS($V$2:$V$300,V10,$H$2:$H$300,H10,$B$2:$B$300,">"&B10)=0,"Y","N")) -> Y | H10: WAH | I10: =IFERROR(VLOOKUP(H10,'DATABASE-DRIFT_LATENT_HP_ERROR'!$A$143:$B$160,2,FALSE()),"") -> Work at Height | J10: I | K10: CLSR07-I | L10: Rescue plan | N10: 1 | P10: Tidak ada suspension trauma rescue plan | Q10: Fatality | R10: Rescue Preparedness | S10: 46156 | T10: =IF(S10="","",YEAR(S10)) -> 2026 | U10: =IF(S10="","","TW "&CHOOSE(ROUNDUP(MONTH(S10)/3,0),"I","II","III","IV")) -> TW II | V10: 13 | W10: CPP MATINDOK | X10: GTG Area | Y10: Scaffolding Dismantling | Z10: PT Petro Teknik Konstruksi | AA10: Iman Sudirman | AB10: Endong Darwilisan Yahya | AC10: Wayan Edi Wijaya
A11: OBS-002 | B11: 1 | C11: N | F11: =IF(A11="","",IF(B11=1,"Baseline",IF(C11="Y","Reverification","Follow-up"))) -> Baseline | G11: =IF(A11="","",IF(COUNTIFS($V$2:$V$300,V11,$H$2:$H$300,H11,$B$2:$B$300,">"&B11)=0,"Y","N")) -> Y | H11: IHE | I11: =IFERROR(VLOOKUP(H11,'DATABASE-DRIFT_LATENT_HP_ERROR'!$A$143:$B$160,2,FALSE()),"") -> Powered System / Isolation of Hazardous Energy | J11: A | K11: CLSR05-A | L11: Safe atmosphere & zero energy verification | M11: 1 | P11: Crew menjelaskan isolasi dan zero energy verification | Q11: Hazardous Energy | R11: Zero Energy State | S11: 46156 | T11: =IF(S11="","",YEAR(S11)) -> 2026 | U11: =IF(S11="","","TW "&CHOOSE(ROUNDUP(MONTH(S11)/3,0),"I","II","III","IV")) -> TW II | V11: 13 | W11: CPP MATINDOK | X11: Condensate Transfer pump | Y11: Pump Overhaul Activity | Z11: PT Petro Teknik Konstruksi | AA11: Iman Sudirman | AB11: Endong Darwilisan Yahya | AC11: Wayan Edi Wijaya
A12: OBS-002 | B12: 1 | C12: N | F12: =IF(A12="","",IF(B12=1,"Baseline",IF(C12="Y","Reverification","Follow-up"))) -> Baseline | G12: =IF(A12="","",IF(COUNTIFS($V$2:$V$300,V12,$H$2:$H$300,H12,$B$2:$B$300,">"&B12)=0,"Y","N")) -> Y | H12: IHE | I12: =IFERROR(VLOOKUP(H12,'DATABASE-DRIFT_LATENT_HP_ERROR'!$A$143:$B$160,2,FALSE()),"") -> Powered System / Isolation of Hazardous Energy | J12: B | K12: CLSR05-B | L12: Isolation point identification | M12: 1 | P12: IA/AA/PA mampu menunjukkan titik isolasi | Q12: Hazardous Energy | R12: Isolation Verification | S12: 46156 | T12: =IF(S12="","",YEAR(S12)) -> 2026 | U12: =IF(S12="","","TW "&CHOOSE(ROUNDUP(MONTH(S12)/3,0),"I","II","III","IV")) -> TW II | V12: 13 | W12: CPP MATINDOK | X12: Condensate Transfer pump | Y12: Pump Overhaul Activity | Z12: PT Petro Teknik Konstruksi | AA12: Iman Sudirman | AB12: Endong Darwilisan Yahya | AC12: Wayan Edi Wijaya
A13: OBS-002 | B13: 1 | C13: N | F13: =IF(A13="","",IF(B13=1,"Baseline",IF(C13="Y","Reverification","Follow-up"))) -> Baseline | G13: =IF(A13="","",IF(COUNTIFS($V$2:$V$300,V13,$H$2:$H$300,H13,$B$2:$B$300,">"&B13)=0,"Y","N")) -> Y | H13: IHE | I13: =IFERROR(VLOOKUP(H13,'DATABASE-DRIFT_LATENT_HP_ERROR'!$A$143:$B$160,2,FALSE()),"") -> Powered System / Isolation of Hazardous Energy | J13: C | K13: CLSR05-C | L13: Individual LOTO implementation | N13: 1 | P13: Hanya IA yang memasang LOTO pada 4 titik isolasi | Q13: Fatality | R13: Individual Protection Barrier | S13: 46156 | T13: =IF(S13="","",YEAR(S13)) -> 2026 | U13: =IF(S13="","","TW "&CHOOSE(ROUNDUP(MONTH(S13)/3,0),"I","II","III","IV")) -> TW II | V13: 13 | W13: CPP MATINDOK | X13: Condensate Transfer pump | Y13: Pump Overhaul Activity | Z13: PT Petro Teknik Konstruksi | AA13: Iman Sudirman | AB13: Endong Darwilisan Yahya | AC13: Wayan Edi Wijaya
A14: OBS-002 | B14: 1 | C14: N | F14: =IF(A14="","",IF(B14=1,"Baseline",IF(C14="Y","Reverification","Follow-up"))) -> Baseline | G14: =IF(A14="","",IF(COUNTIFS($V$2:$V$300,V14,$H$2:$H$300,H14,$B$2:$B$300,">"&B14)=0,"Y","N")) -> Y | H14: IHE | I14: =IFERROR(VLOOKUP(H14,'DATABASE-DRIFT_LATENT_HP_ERROR'!$A$143:$B$160,2,FALSE()),"") -> Powered System / Isolation of Hazardous Energy | J14: D | K14: CLSR05-D | L14: Hazardous energy identification | N14: 1 | P14: Individual LOTO belum diterapkan oleh seluruh personel yang terekspos hazardous energy sehingga meningkatkan risiko unexpected energization | Q14: Fatality | R14: Hazard Identification | S14: 46156 | T14: =IF(S14="","",YEAR(S14)) -> 2026 | U14: =IF(S14="","","TW "&CHOOSE(ROUNDUP(MONTH(S14)/3,0),"I","II","III","IV")) -> TW II | V14: 13 | W14: CPP MATINDOK | X14: Condensate Transfer pump | Y14: Pump Overhaul Activity | Z14: PT Petro Teknik Konstruksi | AA14: Iman Sudirman | AB14: Endong Darwilisan Yahya | AC14: Wayan Edi Wijaya
A15: OBS-002 | B15: 1 | C15: N | F15: =IF(A15="","",IF(B15=1,"Baseline",IF(C15="Y","Reverification","Follow-up"))) -> Baseline | G15: =IF(A15="","",IF(COUNTIFS($V$2:$V$300,V15,$H$2:$H$300,H15,$B$2:$B$300,">"&B15)=0,"Y","N")) -> Y | H15: IHE | I15: =IFERROR(VLOOKUP(H15,'DATABASE-DRIFT_LATENT_HP_ERROR'!$A$143:$B$160,2,FALSE()),"") -> Powered System / Isolation of Hazardous Energy | J15: E | K15: CLSR05-E | L15: Communication of isolation points | M15: 1 | P15: Titik isolasi telah dikomunikasikan kepada pekerja | Q15: Hazardous Energy | R15: Isolation Communication | S15: 46156 | T15: =IF(S15="","",YEAR(S15)) -> 2026 | U15: =IF(S15="","","TW "&CHOOSE(ROUNDUP(MONTH(S15)/3,0),"I","II","III","IV")) -> TW II | V15: 13 | W15: CPP MATINDOK | X15: Condensate Transfer pump | Y15: Pump Overhaul Activity | Z15: PT Petro Teknik Konstruksi | AA15: Iman Sudirman | AB15: Endong Darwilisan Yahya | AC15: Wayan Edi Wijaya
A16: OBS-002 | B16: 1 | C16: N | F16: =IF(A16="","",IF(B16=1,"Baseline",IF(C16="Y","Reverification","Follow-up"))) -> Baseline | G16: =IF(A16="","",IF(COUNTIFS($V$2:$V$300,V16,$H$2:$H$300,H16,$B$2:$B$300,">"&B16)=0,"Y","N")) -> Y | H16: IHE | I16: =IFERROR(VLOOKUP(H16,'DATABASE-DRIFT_LATENT_HP_ERROR'!$A$143:$B$160,2,FALSE()),"") -> Powered System / Isolation of Hazardous Energy | J16: F | K16: CLSR05-F | L16: Residual energy dissipation verification | M16: 1 | P16: Crew menjelaskan verifikasi zero energy dan residual energy dissipation | Q16: Hazardous Energy | R16: Residual Energy Control | S16: 46156 | T16: =IF(S16="","",YEAR(S16)) -> 2026 | U16: =IF(S16="","","TW "&CHOOSE(ROUNDUP(MONTH(S16)/3,0),"I","II","III","IV")) -> TW II | V16: 13 | W16: CPP MATINDOK | X16: Condensate Transfer pump | Y16: Pump Overhaul Activity | Z16: PT Petro Teknik Konstruksi | AA16: Iman Sudirman | AB16: Endong Darwilisan Yahya | AC16: Wayan Edi Wijaya
A17: OBS-002 | B17: 1 | C17: N | F17: =IF(A17="","",IF(B17=1,"Baseline",IF(C17="Y","Reverification","Follow-up"))) -> Baseline | G17: =IF(A17="","",IF(COUNTIFS($V$2:$V$300,V17,$H$2:$H$300,H17,$B$2:$B$300,">"&B17)=0,"Y","N")) -> Y | H17: IHE | I17: =IFERROR(VLOOKUP(H17,'DATABASE-DRIFT_LATENT_HP_ERROR'!$A$143:$B$160,2,FALSE()),"") -> Powered System / Isolation of Hazardous Energy | J17: G | K17: CLSR05-G | L17: First-on last-off lock policy | M17: 1 | P17: Operation lock diterapkan sesuai requirement | Q17: Hazardous Energy | R17: Lock Management | S17: 46156 | T17: =IF(S17="","",YEAR(S17)) -> 2026 | U17: =IF(S17="","","TW "&CHOOSE(ROUNDUP(MONTH(S17)/3,0),"I","II","III","IV")) -> TW II | V17: 13 | W17: CPP MATINDOK | X17: Condensate Transfer pump | Y17: Pump Overhaul Activity | Z17: PT Petro Teknik Konstruksi | AA17: Iman Sudirman | AB17: Endong Darwilisan Yahya | AC17: Wayan Edi Wijaya
A18: OBS-002 | B18: 1 | C18: N | F18: =IF(A18="","",IF(B18=1,"Baseline",IF(C18="Y","Reverification","Follow-up"))) -> Baseline | G18: =IF(A18="","",IF(COUNTIFS($V$2:$V$300,V18,$H$2:$H$300,H18,$B$2:$B$300,">"&B18)=0,"Y","N")) -> Y | H18: IHE | I18: =IFERROR(VLOOKUP(H18,'DATABASE-DRIFT_LATENT_HP_ERROR'!$A$143:$B$160,2,FALSE()),"") -> Powered System / Isolation of Hazardous Energy | J18: H | K18: CLSR05-H | L18: Restoration of isolation points | O18: 1 | P18: Proses normalisasi sistem belum dapat diobservasi | Q18: Hazardous Energy | R18: System Restoration | S18: 46156 | T18: =IF(S18="","",YEAR(S18)) -> 2026 | U18: =IF(S18="","","TW "&CHOOSE(ROUNDUP(MONTH(S18)/3,0),"I","II","III","IV")) -> TW II | V18: 13 | W18: CPP MATINDOK | X18: Condensate Transfer pump | Y18: Pump Overhaul Activity | Z18: PT Petro Teknik Konstruksi | AA18: Iman Sudirman | AB18: Endong Darwilisan Yahya | AC18: Wayan Edi Wijaya
A19: OBS-002 | B19: 1 | C19: N | F19: =IF(A19="","",IF(B19=1,"Baseline",IF(C19="Y","Reverification","Follow-up"))) -> Baseline | G19: =IF(A19="","",IF(COUNTIFS($V$2:$V$300,V19,$H$2:$H$300,H19,$B$2:$B$300,">"&B19)=0,"Y","N")) -> Y | H19: IHE | I19: =IFERROR(VLOOKUP(H19,'DATABASE-DRIFT_LATENT_HP_ERROR'!$A$143:$B$160,2,FALSE()),"") -> Powered System / Isolation of Hazardous Energy | J19: I | K19: CLSR05-I | L19: Mandatory SWA for failed isolation | N19: 1 | P19: Chain lock masih longgar dan berpotensi slip sehingga positive isolation belum optimal | Q19: Fatality | R19: Positive Isolation Integrity | S19: 46156 | T19: =IF(S19="","",YEAR(S19)) -> 2026 | U19: =IF(S19="","","TW "&CHOOSE(ROUNDUP(MONTH(S19)/3,0),"I","II","III","IV")) -> TW II | V19: 13 | W19: CPP MATINDOK | X19: Condensate Transfer pump | Y19: Pump Overhaul Activity | Z19: PT Petro Teknik Konstruksi | AA19: Iman Sudirman | AB19: Endong Darwilisan Yahya | AC19: Wayan Edi Wijaya
A20: OBS-003 | B20: 1 | C20: N | F20: =IF(A20="","",IF(B20=1,"Baseline",IF(C20="Y","Reverification","Follow-up"))) -> Baseline | G20: =IF(A20="","",IF(COUNTIFS($V$2:$V$300,V20,$H$2:$H$300,H20,$B$2:$B$300,">"&B20)=0,"Y","N")) -> Y | H20: IHE | I20: =IFERROR(VLOOKUP(H20,'DATABASE-DRIFT_LATENT_HP_ERROR'!$A$143:$B$160,2,FALSE()),"") -> Powered System / Isolation of Hazardous Energy | J20: A | K20: CLSR05-A | L20: Safe atmosphere & zero energy verification | M20: 1 | P20: Crew menjelaskan isolasi dan zero energy verification | Q20: Hazardous Energy | R20: Zero Energy State | S20: 46157 | T20: =IF(S20="","",YEAR(S20)) -> 2026 | U20: =IF(S20="","","TW "&CHOOSE(ROUNDUP(MONTH(S20)/3,0),"I","II","III","IV")) -> TW II | V20: 13 | W20: CPP DONGGI | X20: Booster Compressor Area | Y20: Alignment Booster Compressor #A | Z20: PT Petro Teknik Konstruksi | AA20: Iman Sudirman | AB20: Yoga Swara Jeni Pratama | AC20: Thamar Thalib Mbau
A21: OBS-003 | B21: 1 | C21: N | F21: =IF(A21="","",IF(B21=1,"Baseline",IF(C21="Y","Reverification","Follow-up"))) -> Baseline | G21: =IF(A21="","",IF(COUNTIFS($V$2:$V$300,V21,$H$2:$H$300,H21,$B$2:$B$300,">"&B21)=0,"Y","N")) -> Y | H21: IHE | I21: =IFERROR(VLOOKUP(H21,'DATABASE-DRIFT_LATENT_HP_ERROR'!$A$143:$B$160,2,FALSE()),"") -> Powered System / Isolation of Hazardous Energy | J21: B | K21: CLSR05-B | L21: Isolation point identification | M21: 1 | P21: IA/AA/PA mampu menunjukkan titik isolasi | Q21: Hazardous Energy | R21: Isolation Verification | S21: 46157 | T21: =IF(S21="","",YEAR(S21)) -> 2026 | U21: =IF(S21="","","TW "&CHOOSE(ROUNDUP(MONTH(S21)/3,0),"I","II","III","IV")) -> TW II | V21: 13 | W21: CPP DONGGI | X21: Booster Compressor Area | Y21: Alignment Booster Compressor #A | Z21: PT Petro Teknik Konstruksi | AA21: Iman Sudirman | AB21: Yoga Swara Jeni Pratama | AC21: Thamar Thalib Mbau
A22: OBS-003 | B22: 1 | C22: N | F22: =IF(A22="","",IF(B22=1,"Baseline",IF(C22="Y","Reverification","Follow-up"))) -> Baseline | G22: =IF(A22="","",IF(COUNTIFS($V$2:$V$300,V22,$H$2:$H$300,H22,$B$2:$B$300,">"&B22)=0,"Y","N")) -> Y | H22: IHE | I22: =IFERROR(VLOOKUP(H22,'DATABASE-DRIFT_LATENT_HP_ERROR'!$A$143:$B$160,2,FALSE()),"") -> Powered System / Isolation of Hazardous Energy | J22: C | K22: CLSR05-C | L22: Individual LOTO implementation | N22: 1 | P22: Hanya IA yang memasang LOTO pada 4 titik isolasi (Motor, Suction valve, Discharge dan Drain Valve) | Q22: Fatality | R22: Individual Protection Barrier | S22: 46157 | T22: =IF(S22="","",YEAR(S22)) -> 2026 | U22: =IF(S22="","","TW "&CHOOSE(ROUNDUP(MONTH(S22)/3,0),"I","II","III","IV")) -> TW II | V22: 13 | W22: CPP DONGGI | X22: Booster Compressor Area | Y22: Alignment Booster Compressor #A | Z22: PT Petro Teknik Konstruksi | AA22: Iman Sudirman | AB22: Yoga Swara Jeni Pratama | AC22: Thamar Thalib Mbau
A23: OBS-003 | B23: 1 | C23: N | F23: =IF(A23="","",IF(B23=1,"Baseline",IF(C23="Y","Reverification","Follow-up"))) -> Baseline | G23: =IF(A23="","",IF(COUNTIFS($V$2:$V$300,V23,$H$2:$H$300,H23,$B$2:$B$300,">"&B23)=0,"Y","N")) -> Y | H23: IHE | I23: =IFERROR(VLOOKUP(H23,'DATABASE-DRIFT_LATENT_HP_ERROR'!$A$143:$B$160,2,FALSE()),"") -> Powered System / Isolation of Hazardous Energy | J23: D | K23: CLSR05-D | L23: Hazardous energy identification | N23: 1 | P23: Walaupun sumber energi berbahaya telah diidentifikasi, individual LOTO belum diterapkan oleh seluruh personel yang terekspos hazardous energy. Kondisi ini meningkatkan risiko unexpected energization akibat miskomunikasi atau kesalahan asumsi bahwa pekerjaan telah selesai | Q23: Fatality | R23: Hazard Identification | S23: 46157 | T23: =IF(S23="","",YEAR(S23)) -> 2026 | U23: =IF(S23="","","TW "&CHOOSE(ROUNDUP(MONTH(S23)/3,0),"I","II","III","IV")) -> TW II | V23: 13 | W23: CPP DONGGI | X23: Booster Compressor Area | Y23: Alignment Booster Compressor #A | Z23: PT Petro Teknik Konstruksi | AA23: Iman Sudirman | AB23: Yoga Swara Jeni Pratama | AC23: Thamar Thalib Mbau
A24: OBS-003 | B24: 1 | C24: N | F24: =IF(A24="","",IF(B24=1,"Baseline",IF(C24="Y","Reverification","Follow-up"))) -> Baseline | G24: =IF(A24="","",IF(COUNTIFS($V$2:$V$300,V24,$H$2:$H$300,H24,$B$2:$B$300,">"&B24)=0,"Y","N")) -> Y | H24: IHE | I24: =IFERROR(VLOOKUP(H24,'DATABASE-DRIFT_LATENT_HP_ERROR'!$A$143:$B$160,2,FALSE()),"") -> Powered System / Isolation of Hazardous Energy | J24: E | K24: CLSR05-E | L24: Communication of isolation points | M24: 1 | P24: Titik isolasi telah dikomunikasikan kepada pekerja | Q24: Hazardous Energy | R24: Isolation Communication | S24: 46157 | T24: =IF(S24="","",YEAR(S24)) -> 2026 | U24: =IF(S24="","","TW "&CHOOSE(ROUNDUP(MONTH(S24)/3,0),"I","II","III","IV")) -> TW II | V24: 13 | W24: CPP DONGGI | X24: Booster Compressor Area | Y24: Alignment Booster Compressor #A | Z24: PT Petro Teknik Konstruksi | AA24: Iman Sudirman | AB24: Yoga Swara Jeni Pratama | AC24: Thamar Thalib Mbau
A25: OBS-003 | B25: 1 | C25: N | F25: =IF(A25="","",IF(B25=1,"Baseline",IF(C25="Y","Reverification","Follow-up"))) -> Baseline | G25: =IF(A25="","",IF(COUNTIFS($V$2:$V$300,V25,$H$2:$H$300,H25,$B$2:$B$300,">"&B25)=0,"Y","N")) -> Y | H25: IHE | I25: =IFERROR(VLOOKUP(H25,'DATABASE-DRIFT_LATENT_HP_ERROR'!$A$143:$B$160,2,FALSE()),"") -> Powered System / Isolation of Hazardous Energy | J25: F | K25: CLSR05-F | L25: Residual energy dissipation verification | M25: 1 | P25: Crew menjelaskan verifikasi zero energy dan residual energy dissipation | Q25: Hazardous Energy | R25: Residual Energy Control | S25: 46157 | T25: =IF(S25="","",YEAR(S25)) -> 2026 | U25: =IF(S25="","","TW "&CHOOSE(ROUNDUP(MONTH(S25)/3,0),"I","II","III","IV")) -> TW II | V25: 13 | W25: CPP DONGGI | X25: Booster Compressor Area | Y25: Alignment Booster Compressor #A | Z25: PT Petro Teknik Konstruksi | AA25: Iman Sudirman | AB25: Yoga Swara Jeni Pratama | AC25: Thamar Thalib Mbau
A26: OBS-003 | B26: 1 | C26: N | F26: =IF(A26="","",IF(B26=1,"Baseline",IF(C26="Y","Reverification","Follow-up"))) -> Baseline | G26: =IF(A26="","",IF(COUNTIFS($V$2:$V$300,V26,$H$2:$H$300,H26,$B$2:$B$300,">"&B26)=0,"Y","N")) -> Y | H26: IHE | I26: =IFERROR(VLOOKUP(H26,'DATABASE-DRIFT_LATENT_HP_ERROR'!$A$143:$B$160,2,FALSE()),"") -> Powered System / Isolation of Hazardous Energy | J26: G | K26: CLSR05-G | L26: First-on last-off lock policy | M26: 1 | P26: Operation lock diterapkan sesuai requirement | Q26: Hazardous Energy | R26: Lock Management | S26: 46157 | T26: =IF(S26="","",YEAR(S26)) -> 2026 | U26: =IF(S26="","","TW "&CHOOSE(ROUNDUP(MONTH(S26)/3,0),"I","II","III","IV")) -> TW II | V26: 13 | W26: CPP DONGGI | X26: Booster Compressor Area | Y26: Alignment Booster Compressor #A | Z26: PT Petro Teknik Konstruksi | AA26: Iman Sudirman | AB26: Yoga Swara Jeni Pratama | AC26: Thamar Thalib Mbau
A27: OBS-003 | B27: 1 | C27: N | F27: =IF(A27="","",IF(B27=1,"Baseline",IF(C27="Y","Reverification","Follow-up"))) -> Baseline | G27: =IF(A27="","",IF(COUNTIFS($V$2:$V$300,V27,$H$2:$H$300,H27,$B$2:$B$300,">"&B27)=0,"Y","N")) -> Y | H27: IHE | I27: =IFERROR(VLOOKUP(H27,'DATABASE-DRIFT_LATENT_HP_ERROR'!$A$143:$B$160,2,FALSE()),"") -> Powered System / Isolation of Hazardous Energy | J27: H | K27: CLSR05-H | L27: Restoration of isolation points | O27: 1 | P27: Proses normalisasi sistem belum dapat diobservasi | Q27: Hazardous Energy | R27: System Restoration | S27: 46157 | T27: =IF(S27="","",YEAR(S27)) -> 2026 | U27: =IF(S27="","","TW "&CHOOSE(ROUNDUP(MONTH(S27)/3,0),"I","II","III","IV")) -> TW II | V27: 13 | W27: CPP DONGGI | X27: Booster Compressor Area | Y27: Alignment Booster Compressor #A | Z27: PT Petro Teknik Konstruksi | AA27: Iman Sudirman | AB27: Yoga Swara Jeni Pratama | AC27: Thamar Thalib Mbau
A28: OBS-003 | B28: 1 | C28: N | F28: =IF(A28="","",IF(B28=1,"Baseline",IF(C28="Y","Reverification","Follow-up"))) -> Baseline | G28: =IF(A28="","",IF(COUNTIFS($V$2:$V$300,V28,$H$2:$H$300,H28,$B$2:$B$300,">"&B28)=0,"Y","N")) -> Y | H28: IHE | I28: =IFERROR(VLOOKUP(H28,'DATABASE-DRIFT_LATENT_HP_ERROR'!$A$143:$B$160,2,FALSE()),"") -> Powered System / Isolation of Hazardous Energy | J28: I | K28: CLSR05-I | L28: Mandatory SWA for failed isolation | N28: 1 | P28: PA dan pekerja tidak memasang LOTO atau INDIVIDUAL ACCOUNTABILITY tidak diimplementasikan | Q28: Fatality | R28: Individual Accountability | S28: 46157 | T28: =IF(S28="","",YEAR(S28)) -> 2026 | U28: =IF(S28="","","TW "&CHOOSE(ROUNDUP(MONTH(S28)/3,0),"I","II","III","IV")) -> TW II | V28: 13 | W28: CPP DONGGI | X28: Booster Compressor Area | Y28: Alignment Booster Compressor #A | Z28: PT Petro Teknik Konstruksi | AA28: Iman Sudirman | AB28: Yoga Swara Jeni Pratama | AC28: Thamar Thalib Mbau
A29: OBS-004 | B29: 1 | C29: N | F29: =IF(A29="","",IF(B29=1,"Baseline",IF(C29="Y","Reverification","Follow-up"))) -> Baseline | G29: =IF(A29="","",IF(COUNTIFS($V$2:$V$300,V29,$H$2:$H$300,H29,$B$2:$B$300,">"&B29)=0,"Y","N")) -> Y | H29: GD | I29: =IFERROR(VLOOKUP(H29,'DATABASE-DRIFT_LATENT_HP_ERROR'!$A$143:$B$160,2,FALSE()),"") -> Ground Disturbance or Excavation | J29: A | K29: CLSR08-A | L29: Underground utility hazard identification | M29: 1 | P29: Crew telah melakukan identifikasi bahaya underground utilities menggunakan excavation certificate dan penggalian manual | Q29: Underground Utility Strike | R29: Utility Identification | S29: 46157 | T29: =IF(S29="","",YEAR(S29)) -> 2026 | U29: =IF(S29="","","TW "&CHOOSE(ROUNDUP(MONTH(S29)/3,0),"I","II","III","IV")) -> TW II | V29: 13 | W29: CPP DONGGI | X29: Hydrant Line Area | Y29: Excavation for Hydrant Pipe Leak Repair | Z29: PT Petro Teknik Konstruksi | AA29: Iman Sudirman | AB29: Yoga Swara Jeni Pratama | AC29: Thamar Thalib Mbau
A30: OBS-004 | B30: 1 | C30: N | F30: =IF(A30="","",IF(B30=1,"Baseline",IF(C30="Y","Reverification","Follow-up"))) -> Baseline | G30: =IF(A30="","",IF(COUNTIFS($V$2:$V$300,V30,$H$2:$H$300,H30,$B$2:$B$300,">"&B30)=0,"Y","N")) -> Y | H30: GD | I30: =IFERROR(VLOOKUP(H30,'DATABASE-DRIFT_LATENT_HP_ERROR'!$A$143:$B$160,2,FALSE()),"") -> Ground Disturbance or Excavation | J30: B | K30: CLSR08-B | L30: Personnel safety relative to excavating equipment | O30: 1 | P30: Aktivitas excavating equipment tidak sedang berlangsung saat observasi dilakukan | Q30: Line of Fire | R30: Equipment Separation | S30: 46157 | T30: =IF(S30="","",YEAR(S30)) -> 2026 | U30: =IF(S30="","","TW "&CHOOSE(ROUNDUP(MONTH(S30)/3,0),"I","II","III","IV")) -> TW II | V30: 13 | W30: CPP DONGGI | X30: Hydrant Line Area | Y30: Excavation for Hydrant Pipe Leak Repair | Z30: PT Petro Teknik Konstruksi | AA30: Iman Sudirman | AB30: Yoga Swara Jeni Pratama | AC30: Thamar Thalib Mbau
A31: OBS-004 | B31: 1 | C31: N | F31: =IF(A31="","",IF(B31=1,"Baseline",IF(C31="Y","Reverification","Follow-up"))) -> Baseline | G31: =IF(A31="","",IF(COUNTIFS($V$2:$V$300,V31,$H$2:$H$300,H31,$B$2:$B$300,">"&B31)=0,"Y","N")) -> Y | H31: GD | I31: =IFERROR(VLOOKUP(H31,'DATABASE-DRIFT_LATENT_HP_ERROR'!$A$143:$B$160,2,FALSE()),"") -> Ground Disturbance or Excavation | J31: C | K31: CLSR08-C | L31: Significant excavation hazard identification | N31: 1 | P31: Potensi bahaya underground electrical cable belum teridentifikasi secara spesifik di dalam Risk Assessment (RA) dan JSA karena pekerjaan telah mengacu pada excavation certificate | Q31: Electrical Contact / Fatality | R31: Hazard Identification | S31: 46157 | T31: =IF(S31="","",YEAR(S31)) -> 2026 | U31: =IF(S31="","","TW "&CHOOSE(ROUNDUP(MONTH(S31)/3,0),"I","II","III","IV")) -> TW II | V31: 13 | W31: CPP DONGGI | X31: Hydrant Line Area | Y31: Excavation for Hydrant Pipe Leak Repair | Z31: PT Petro Teknik Konstruksi | AA31: Iman Sudirman | AB31: Yoga Swara Jeni Pratama | AC31: Thamar Thalib Mbau
A32: OBS-004 | B32: 1 | C32: N | F32: =IF(A32="","",IF(B32=1,"Baseline",IF(C32="Y","Reverification","Follow-up"))) -> Baseline | G32: =IF(A32="","",IF(COUNTIFS($V$2:$V$300,V32,$H$2:$H$300,H32,$B$2:$B$300,">"&B32)=0,"Y","N")) -> Y | H32: GD | I32: =IFERROR(VLOOKUP(H32,'DATABASE-DRIFT_LATENT_HP_ERROR'!$A$143:$B$160,2,FALSE()),"") -> Ground Disturbance or Excavation | J32: D | K32: CLSR08-D | L32: Hidden hazard and soil stability verification | M32: 1 | P32: Crew menjelaskan pengendalian terhadap kondisi tanah dan hidden hazard excavation | Q32: Cave-In Hazard | R32: Soil Stability Verification | S32: 46157 | T32: =IF(S32="","",YEAR(S32)) -> 2026 | U32: =IF(S32="","","TW "&CHOOSE(ROUNDUP(MONTH(S32)/3,0),"I","II","III","IV")) -> TW II | V32: 13 | W32: CPP DONGGI | X32: Hydrant Line Area | Y32: Excavation for Hydrant Pipe Leak Repair | Z32: PT Petro Teknik Konstruksi | AA32: Iman Sudirman | AB32: Yoga Swara Jeni Pratama | AC32: Thamar Thalib Mbau
A33: OBS-004 | B33: 1 | C33: N | F33: =IF(A33="","",IF(B33=1,"Baseline",IF(C33="Y","Reverification","Follow-up"))) -> Baseline | G33: =IF(A33="","",IF(COUNTIFS($V$2:$V$300,V33,$H$2:$H$300,H33,$B$2:$B$300,">"&B33)=0,"Y","N")) -> Y | H33: GD | I33: =IFERROR(VLOOKUP(H33,'DATABASE-DRIFT_LATENT_HP_ERROR'!$A$143:$B$160,2,FALSE()),"") -> Ground Disturbance or Excavation | J33: E | K33: CLSR08-E | L33: Mandatory SWA and permit revalidation | N33: 1 | P33: Pekerja dan pengawas telah melakukan SWA setelah ditemukan kabel bawah tanah yang tidak teridentifikasi, namun mandatory permit revalidation terhadap unidentified underground utilities belum sepenuhnya dipahami | Q33: Utility Strike / Fatality | R33: SWA & Permit Revalidation | S33: 46157 | T33: =IF(S33="","",YEAR(S33)) -> 2026 | U33: =IF(S33="","","TW "&CHOOSE(ROUNDUP(MONTH(S33)/3,0),"I","II","III","IV")) -> TW II | V33: 13 | W33: CPP DONGGI | X33: Hydrant Line Area | Y33: Excavation for Hydrant Pipe Leak Repair | Z33: PT Petro Teknik Konstruksi | AA33: Iman Sudirman | AB33: Yoga Swara Jeni Pratama | AC33: Thamar Thalib Mbau
A34: OBS-005 | B34: 1 | C34: N | F34: =IF(A34="","",IF(B34=1,"Baseline",IF(C34="Y","Reverification","Follow-up"))) -> Baseline | G34: =IF(A34="","",IF(COUNTIFS($V$2:$V$300,V34,$H$2:$H$300,H34,$B$2:$B$300,">"&B34)=0,"Y","N")) -> Y | H34: WAH | I34: =IFERROR(VLOOKUP(H34,'DATABASE-DRIFT_LATENT_HP_ERROR'!$A$143:$B$160,2,FALSE()),"") -> Work at Height | J34: A | K34: CLSR07-A | L34: Pemahaman fall restraint vs fall arrest | N34: 1 | P34: Para pekerja yang berada diatas scaffolding sudah mencoba menggunakan fall restraint system (D-ring dibelakang dan lanyard tanpa absorber). Tetapi karena konfigurasi dari lanyard dan titik angkur yang kurang tepat, masih memungkinkan pekerja mencapai bahaya jatuh | Q34: Fall from height | R34: Fall Protection | S34: 46163 | T34: =IF(S34="","",YEAR(S34)) -> 2026 | U34: =IF(S34="","","TW "&CHOOSE(ROUNDUP(MONTH(S34)/3,0),"I","II","III","IV")) -> TW II | V34: 11 | W34: CPP GUNDIH | X34: New GTG Area | Y34: Erection Struktur Shelter New GTG | Z34: PT Petrowell Energy | AA34: Iman Sudirman | AB34: Andy Kurniawan | AC34: Angga Saptya Pratama & Aldila Faza Zulfah | AD34: Yusuf A. | AE34: Hawis A. | AF34: Rusman
A35: OBS-005 | B35: 1 | C35: N | F35: =IF(A35="","",IF(B35=1,"Baseline",IF(C35="Y","Reverification","Follow-up"))) -> Baseline | G35: =IF(A35="","",IF(COUNTIFS($V$2:$V$300,V35,$H$2:$H$300,H35,$B$2:$B$300,">"&B35)=0,"Y","N")) -> Y | H35: WAH | I35: =IFERROR(VLOOKUP(H35,'DATABASE-DRIFT_LATENT_HP_ERROR'!$A$143:$B$160,2,FALSE()),"") -> Work at Height | J35: B | K35: CLSR07-B | L35: Pemahaman restraint vs arrest lanyard | N35: 1 | P35: Didalam dokumen Start Work Checklist (SWC) sebagai Human performance tools (HPT) tertulis penggunaan fall restraint dan/atau fall arrest, tetapi AA, PA dan pekerja tidak tahu perbedaan antara fall restraint dan arrest | Q35: Fall from height | R35: Correct Equipment | S35: 46163 | T35: =IF(S35="","",YEAR(S35)) -> 2026 | U35: =IF(S35="","","TW "&CHOOSE(ROUNDUP(MONTH(S35)/3,0),"I","II","III","IV")) -> TW II | V35: 11 | W35: CPP GUNDIH | X35: New GTG Area | Y35: Erection Struktur Shelter New GTG | Z35: PT Petrowell Energy | AA35: Iman Sudirman | AB35: Andy Kurniawan | AC35: Angga Saptya Pratama & Aldila Faza Zulfah | AD35: Yusuf A. | AE35: Hawis A. | AF35: Rusman
A36: OBS-005 | B36: 1 | C36: N | F36: =IF(A36="","",IF(B36=1,"Baseline",IF(C36="Y","Reverification","Follow-up"))) -> Baseline | G36: =IF(A36="","",IF(COUNTIFS($V$2:$V$300,V36,$H$2:$H$300,H36,$B$2:$B$300,">"&B36)=0,"Y","N")) -> Y | H36: WAH | I36: =IFERROR(VLOOKUP(H36,'DATABASE-DRIFT_LATENT_HP_ERROR'!$A$143:$B$160,2,FALSE()),"") -> Work at Height | J36: C | K36: CLSR07-C | L36: Free fall distance calculation | N36: 1 | P36: Tidak ditemukan dokumen yang menghitung jarak jatuh sehingga jarak safety factor diketahui | Q36: Fatality | R36: Engineering Safeguard | S36: 46163 | T36: =IF(S36="","",YEAR(S36)) -> 2026 | U36: =IF(S36="","","TW "&CHOOSE(ROUNDUP(MONTH(S36)/3,0),"I","II","III","IV")) -> TW II | V36: 11 | W36: CPP GUNDIH | X36: New GTG Area | Y36: Erection Struktur Shelter New GTG | Z36: PT Petrowell Energy | AA36: Iman Sudirman | AB36: Andy Kurniawan | AC36: Angga Saptya Pratama & Aldila Faza Zulfah | AD36: Yusuf A. | AE36: Hawis A. | AF36: Rusman
A37: OBS-005 | B37: 1 | C37: N | F37: =IF(A37="","",IF(B37=1,"Baseline",IF(C37="Y","Reverification","Follow-up"))) -> Baseline | G37: =IF(A37="","",IF(COUNTIFS($V$2:$V$300,V37,$H$2:$H$300,H37,$B$2:$B$300,">"&B37)=0,"Y","N")) -> Y | H37: WAH | I37: =IFERROR(VLOOKUP(H37,'DATABASE-DRIFT_LATENT_HP_ERROR'!$A$143:$B$160,2,FALSE()),"") -> Work at Height | J37: D | K37: CLSR07-D | L37: Anchorage point verification | N37: 1 | P37: Anchorage point belum diverifikasi oleh personel kompeten dan requirement kekuatan anchor point belum dipahami secara memadai | Q37: Fall Protection | R37: Anchorage Integrity | S37: 46163 | T37: =IF(S37="","",YEAR(S37)) -> 2026 | U37: =IF(S37="","","TW "&CHOOSE(ROUNDUP(MONTH(S37)/3,0),"I","II","III","IV")) -> TW II | V37: 11 | W37: CPP GUNDIH | X37: New GTG Area | Y37: Erection Struktur Shelter New GTG | Z37: PT Petrowell Energy | AA37: Iman Sudirman | AB37: Andy Kurniawan | AC37: Angga Saptya Pratama & Aldila Faza Zulfah | AD37: Yusuf A. | AE37: Hawis A. | AF37: Rusman
A38: OBS-005 | B38: 1 | C38: N | F38: =IF(A38="","",IF(B38=1,"Baseline",IF(C38="Y","Reverification","Follow-up"))) -> Baseline | G38: =IF(A38="","",IF(COUNTIFS($V$2:$V$300,V38,$H$2:$H$300,H38,$B$2:$B$300,">"&B38)=0,"Y","N")) -> Y | H38: WAH | I38: =IFERROR(VLOOKUP(H38,'DATABASE-DRIFT_LATENT_HP_ERROR'!$A$143:$B$160,2,FALSE()),"") -> Work at Height | J38: E | K38: CLSR07-E | L38: 100% tie off | N38: 1 | P38: Ditemukan satu pekerja tidak 100% tie-off saat mau berpindah posisi pada ketinggian sekitar 6 m (diatas struktur roof) | Q38: Fall Protection | R38: Continuous Connection | S38: 46163 | T38: =IF(S38="","",YEAR(S38)) -> 2026 | U38: =IF(S38="","","TW "&CHOOSE(ROUNDUP(MONTH(S38)/3,0),"I","II","III","IV")) -> TW II | V38: 11 | W38: CPP GUNDIH | X38: New GTG Area | Y38: Erection Struktur Shelter New GTG | Z38: PT Petrowell Energy | AA38: Iman Sudirman | AB38: Andy Kurniawan | AC38: Angga Saptya Pratama & Aldila Faza Zulfah | AD38: Yusuf A. | AE38: Hawis A. | AF38: Rusman
A39: OBS-005 | B39: 1 | C39: N | F39: =IF(A39="","",IF(B39=1,"Baseline",IF(C39="Y","Reverification","Follow-up"))) -> Baseline | G39: =IF(A39="","",IF(COUNTIFS($V$2:$V$300,V39,$H$2:$H$300,H39,$B$2:$B$300,">"&B39)=0,"Y","N")) -> Y | H39: WAH | I39: =IFERROR(VLOOKUP(H39,'DATABASE-DRIFT_LATENT_HP_ERROR'!$A$143:$B$160,2,FALSE()),"") -> Work at Height | J39: F | K39: CLSR07-F | L39: Swing fall prevention | M39: 1 | P39: Titik anchorage telah diposisikan untuk mengurangi potensi kontak dengan struktur saat jatuh | Q39: Secondary impact | R39: Safe Anchorage | S39: 46163 | T39: =IF(S39="","",YEAR(S39)) -> 2026 | U39: =IF(S39="","","TW "&CHOOSE(ROUNDUP(MONTH(S39)/3,0),"I","II","III","IV")) -> TW II | V39: 11 | W39: CPP GUNDIH | X39: New GTG Area | Y39: Erection Struktur Shelter New GTG | Z39: PT Petrowell Energy | AA39: Iman Sudirman | AB39: Andy Kurniawan | AC39: Angga Saptya Pratama & Aldila Faza Zulfah | AD39: Yusuf A. | AE39: Hawis A. | AF39: Rusman
A40: OBS-005 | B40: 1 | C40: N | F40: =IF(A40="","",IF(B40=1,"Baseline",IF(C40="Y","Reverification","Follow-up"))) -> Baseline | G40: =IF(A40="","",IF(COUNTIFS($V$2:$V$300,V40,$H$2:$H$300,H40,$B$2:$B$300,">"&B40)=0,"Y","N")) -> Y | H40: WAH | I40: =IFERROR(VLOOKUP(H40,'DATABASE-DRIFT_LATENT_HP_ERROR'!$A$143:$B$160,2,FALSE()),"") -> Work at Height | J40: G | K40: CLSR07-G | L40: Inspection equipment | M40: 1 | P40: Harness, lanyard dan scaffolding telah diinspeksi sebelum digunakan | Q40: Equipment Integrity | R40: Equipment Inspection | S40: 46163 | T40: =IF(S40="","",YEAR(S40)) -> 2026 | U40: =IF(S40="","","TW "&CHOOSE(ROUNDUP(MONTH(S40)/3,0),"I","II","III","IV")) -> TW II | V40: 11 | W40: CPP GUNDIH | X40: New GTG Area | Y40: Erection Struktur Shelter New GTG | Z40: PT Petrowell Energy | AA40: Iman Sudirman | AB40: Andy Kurniawan | AC40: Angga Saptya Pratama & Aldila Faza Zulfah | AD40: Yusuf A. | AE40: Hawis A. | AF40: Rusman
...

Sheet INPUT-Error_Traps
A1: Obs_ID | B1: Protocols | C1: Protocols | D1: Error Trap Catergories | E1: Error Trap | F1: Comments
A2: OBS-001 | B2: WAH | C2: =IFERROR(VLOOKUP(B2,'DATABASE-DRIFT_LATENT_HP_ERROR'!$A$143:$B$160,2,FALSE()),"") -> Work at Height | D2: Individual_Factor | E2: Complacency | F2: Pekerja terlalu familiar terhadap aktivitas scaffolding sehingga questioning attitude terhadap bahaya fall hazard menurun.
A3: OBS-001 | B3: WAH | C3: =IFERROR(VLOOKUP(B3,'DATABASE-DRIFT_LATENT_HP_ERROR'!$A$143:$B$160,2,FALSE()),"") -> Work at Height | D3: Organizational_Factor | E3: Inadequate Training | F3: Personel belum memahami hierarchy of control WAH, fall restraint vs fall arrest, serta bahaya suspension trauma.
A4: OBS-001 | B4: WAH | C4: =IFERROR(VLOOKUP(B4,'DATABASE-DRIFT_LATENT_HP_ERROR'!$A$143:$B$160,2,FALSE()),"") -> Work at Height | D4: Task_Demands | E4: Vague Written Guidance | F4: Prosedur dan PTW belum menjelaskan anchorage point, free fall distance, swing fall hazard, dan rescue requirement secara detail.
A5: OBS-001 | B5: WAH | C5: =IFERROR(VLOOKUP(B5,'DATABASE-DRIFT_LATENT_HP_ERROR'!$A$143:$B$160,2,FALSE()),"") -> Work at Height | D5: Work_Environment | E5: Limited Tool Availability | F5: Rescue equipment dan perangkat pendukung suspension trauma rescue belum tersedia secara memadai di lokasi kerja.
A6: OBS-002 | B6: IHE | C6: =IFERROR(VLOOKUP(B6,'DATABASE-DRIFT_LATENT_HP_ERROR'!$A$143:$B$160,2,FALSE()),"") -> Powered System / Isolation of Hazardous Energy | D6: Individual_Factor | E6: Complacency | F6: Personel menganggap pengamanan isolasi oleh IA sudah cukup sehingga individual LOTO tidak diterapkan oleh seluruh pekerja terekspos.
A7: OBS-002 | B7: IHE | C7: =IFERROR(VLOOKUP(B7,'DATABASE-DRIFT_LATENT_HP_ERROR'!$A$143:$B$160,2,FALSE()),"") -> Powered System / Isolation of Hazardous Energy | D7: Organizational_Factor | E7: Inadequate Training | F7: Pemahaman terkait filosofi “one man one lock one key” dan individual accountability terhadap hazardous energy masih lemah.
A8: OBS-002 | B8: IHE | C8: =IFERROR(VLOOKUP(B8,'DATABASE-DRIFT_LATENT_HP_ERROR'!$A$143:$B$160,2,FALSE()),"") -> Powered System / Isolation of Hazardous Energy | D8: Task_Demands | E8: Vague Written Guidance | F8: Implementasi group lock box dan individual LOTO belum dijelaskan secara kuat dan konsisten dalam praktik lapangan.
A9: OBS-002 | B9: IHE | C9: =IFERROR(VLOOKUP(B9,'DATABASE-DRIFT_LATENT_HP_ERROR'!$A$143:$B$160,2,FALSE()),"") -> Powered System / Isolation of Hazardous Energy | D9: Work_Environment | E9: Limited Tool Availability | F9: Ketersediaan dan distribusi equipment LOTO kepada seluruh pekerja belum optimal.
A10: OBS-003 | B10: IHE | C10: =IFERROR(VLOOKUP(B10,'DATABASE-DRIFT_LATENT_HP_ERROR'!$A$143:$B$160,2,FALSE()),"") -> Powered System / Isolation of Hazardous Energy | D10: Individual_Factor | E10: Complacency | F10: Personel mulai terbiasa menggunakan pengendalian administratif tanpa personal lock sebagai barrier individual protection.
A11: OBS-003 | B11: IHE | C11: =IFERROR(VLOOKUP(B11,'DATABASE-DRIFT_LATENT_HP_ERROR'!$A$143:$B$160,2,FALSE()),"") -> Powered System / Isolation of Hazardous Energy | D11: Organizational_Factor | E11: Inadequate Training | F11: Komunikasi mengenai mandatory individual LOTO belum dipahami konsisten oleh seluruh personel yang terekspos hazardous energy.
A12: OBS-003 | B12: IHE | C12: =IFERROR(VLOOKUP(B12,'DATABASE-DRIFT_LATENT_HP_ERROR'!$A$143:$B$160,2,FALSE()),"") -> Powered System / Isolation of Hazardous Energy | D12: Task_Demands | E12: Inadequate Job Design | F12: Penggunaan chain lock pada valve isolation dilakukan tanpa guidance engineering yang detail terkait efektivitas positive isolation.
A13: OBS-003 | B13: IHE | C13: =IFERROR(VLOOKUP(B13,'DATABASE-DRIFT_LATENT_HP_ERROR'!$A$143:$B$160,2,FALSE()),"") -> Powered System / Isolation of Hazardous Energy | D13: Work_Environment | E13: Limited Tool Availability | F13: Handwheel valve lockout cover atau universal cable valve lockout yang lebih sesuai belum tersedia memadai.
... A57: OBS-023 | B57: IHE | C57: =IFERROR(VLOOKUP(B57,'DATABASE-DRIFT_LATENT_HP_ERROR'!$A$143:$B$160,2,FALSE()),"") -> Powered System / Isolation of Hazardous Energy | D57: Individual Factor | E57: Complacency | F57: Checked in source observation document OBS-023.

Sheet INPUT-HP_Tools
A1: Obs_ID | B1: Protocols | C1: Protocols | D1: HP_tool | E1: Tujuan | F1: Kapan digunakan | G1: Cara pakai / implementasi | H1: Effectiveness_Notes
A2: OBS-001 | B2: WAH | C2: =IFERROR(VLOOKUP(B2,'DATABASE-DRIFT_LATENT_HP_ERROR'!$A$143:$B$160,2,FALSE()),"") -> Work at Height | D2: Stop and Get Help | E2: Menghentikan pekerjaan saat terdapat ketidakpastian terhadap critical safeguard WAH | F2: Saat pekerja tidak memahami fall restraint vs fall arrest, suspension trauma hazard, dan rescue preparedness | G2: Hentikan pekerjaan dan lakukan coaching/verifikasi dengan personel kompeten sebelum pekerjaan dilanjutkan | H2: SWA digunakan untuk coaching terhadap critical safeguard WAH, namun gap kompetensi dan engineering understanding masih ditemukan
A3: OBS-001 | B3: WAH | C3: =IFERROR(VLOOKUP(B3,'DATABASE-DRIFT_LATENT_HP_ERROR'!$A$143:$B$160,2,FALSE()),"") -> Work at Height | D3: Pre-task brief | E3: Memastikan pekerja memahami hazard dan safeguard pekerjaan WAH | F3: Sebelum pekerjaan dismantling scaffolding dimulai | G3: Bahas hazard jatuh, dropped object, anchor point, dan rescue preparedness | H3: Briefing lebih dominan administratif dan belum membangun pemahaman engineering consequence secara mendalam
A4: OBS-002 | B4: IHE | C4: =IFERROR(VLOOKUP(B4,'DATABASE-DRIFT_LATENT_HP_ERROR'!$A$143:$B$160,2,FALSE()),"") -> Powered System / Isolation of Hazardous Energy | D4: Stop and Get Help | E4: Menghentikan pekerjaan saat ditemukan gap implementasi individual LOTO | F4: Saat diketahui hanya IA yang memasang LOTO sementara pekerja lain belum protected by personal lock | G4: Hentikan pekerjaan dan lakukan review ulang implementasi individual LOTO sebelum pekerjaan dilanjutkan | H4: Coaching berhasil meningkatkan awareness penggunaan LOTO BOX sebagai additional barrier
A5: OBS-002 | B5: IHE | C5: =IFERROR(VLOOKUP(B5,'DATABASE-DRIFT_LATENT_HP_ERROR'!$A$143:$B$160,2,FALSE()),"") -> Powered System / Isolation of Hazardous Energy | D5: Pre-task brief | E5: Memastikan pekerja memahami hazardous energy exposure | F5: Sebelum pekerjaan overhaul dan alignment pompa dimulai | G5: Bahas isolation point, zero energy verification, dan individual accountability | H5: Briefing belum cukup menekankan fatal risk unexpected energization
A6: OBS-003 | B6: IHE | C6: =IFERROR(VLOOKUP(B6,'DATABASE-DRIFT_LATENT_HP_ERROR'!$A$143:$B$160,2,FALSE()),"") -> Powered System / Isolation of Hazardous Energy | D6: Stop and Get Help | E6: Menghentikan pekerjaan saat ditemukan gap individual LOTO | F6: Saat pekerja belum memasang personal lock pada pekerjaan alignment booster compressor | G6: Pekerjaan dihentikan sementara untuk review implementasi LOTO | H6: Coaching meningkatkan awareness terhadap kebutuhan personal protection barrier
A7: OBS-003 | B7: IHE | C7: =IFERROR(VLOOKUP(B7,'DATABASE-DRIFT_LATENT_HP_ERROR'!$A$143:$B$160,2,FALSE()),"") -> Powered System / Isolation of Hazardous Energy | D7: Pre-task brief | E7: Membangun shared understanding terhadap hazardous energy | F7: Sebelum alignment booster compressor dilakukan | G7: Review ICC, titik isolasi, dan exposure hazardous energy | H7: Briefing belum memastikan implementasi individual accountability
A8: OBS-004 | B8: GD | C8: =IFERROR(VLOOKUP(B8,'DATABASE-DRIFT_LATENT_HP_ERROR'!$A$143:$B$160,2,FALSE()),"") -> Ground Disturbance or Excavation | D8: Stop and Get Help | E8: Menghentikan pekerjaan saat ditemukan utilitas bawah tanah yang tidak teridentifikasi | F8: Saat excavation menemukan kabel bawah tanah pada kedalaman ±0.5 meter | G8: Hentikan excavation dan lakukan reassessment sebelum pekerjaan dilanjutkan | H8: SWA telah digunakan dengan baik sebagai escalation trigger
A9: OBS-004 | B9: GD | C9: =IFERROR(VLOOKUP(B9,'DATABASE-DRIFT_LATENT_HP_ERROR'!$A$143:$B$160,2,FALSE()),"") -> Ground Disturbance or Excavation | D9: Pre-task brief | E9: Memastikan pekerja memahami excavation hazard dan SWA trigger | F9: Sebelum excavation dimulai | G9: Bahas underground utilities, cave-in hazard, dan permit revalidation | H9: Briefing belum cukup membangun awareness escalation hazard
A10: OBS-005 | B10: WAH | C10: =IFERROR(VLOOKUP(B10,'DATABASE-DRIFT_LATENT_HP_ERROR'!$A$143:$B$160,2,FALSE()),"") -> Work at Height | D10: Stop and Get Help | E10: Menghentikan pekerjaan saat rescue readiness dan tie-off belum memadai | F10: Saat rescue plan dan safety standby person belum tersedia | G10: Hentikan pekerjaan untuk verifikasi rescue preparedness dan safeguard | H10: SWA digunakan untuk coaching terhadap suspension trauma hazard dan rescue readiness
A11: OBS-005 | B11: WAH | C11: =IFERROR(VLOOKUP(B11,'DATABASE-DRIFT_LATENT_HP_ERROR'!$A$143:$B$160,2,FALSE()),"") -> Work at Height | D11: Pre-task brief | E11: Membangun pemahaman terhadap critical safeguard pekerjaan WAH | F11: Sebelum erection scaffolding dimulai | G11: Bahas anchor point, free fall distance, swing fall, dan rescue plan | H11: Briefing masih dominan administratif dan belum membahas engineering consequence secara mendalam
A12: OBS-006 | B12: WAH | C12: =IFERROR(VLOOKUP(B12,'DATABASE-DRIFT_LATENT_HP_ERROR'!$A$143:$B$160,2,FALSE()),"") -> Work at Height | D12: Stop and Get Help | E12: Menghentikan pekerjaan saat critical safeguard Work at Height tidak siap | F12: Saat ditemukan gap pada rescue readiness, verification, atau safeguard utama | G12: Hentikan pekerjaan WAH pada scaffolding/heat exchanger, lakukan reassessment, lengkapi safeguard, lalu revalidasi permit/SWC | H12: SWA/stop-work digunakan sebagai trigger coaching dan perbaikan safeguard lapangan
A13: OBS-006 | B13: WAH | C13: =IFERROR(VLOOKUP(B13,'DATABASE-DRIFT_LATENT_HP_ERROR'!$A$143:$B$160,2,FALSE()),"") -> Work at Height | D13: Pre-task brief | E13: Membangun shared understanding terhadap critical safeguard Work at Height | F13: Sebelum pekerjaan high-risk dimulai atau setelah kondisi berubah | G13: Bahas scope, hazard, critical safeguard, emergency/rescue plan, dan stop-work trigger pada WAH pada scaffolding/heat exchanger | H13: Briefing perlu lebih teknikal, bukan hanya administratif
... A40: OBS-023 | B40: IHE | C40: =IFERROR(VLOOKUP(B40,'DATABASE-DRIFT_LATENT_HP_ERROR'!$A$143:$B$160,2,FALSE()),"") -> Powered System / Isolation of Hazardous Energy | D40: Pre-task brief | E40: Membangun shared understanding sebelum pekerjaan dimulai | F40: Sebelum pekerjaan high risk | G40: Diskusikan scope, hazard, critical safeguard, error traps, SWA trigger, rescue plan, dan role tiap personel. | H40: Checked/used in source observation document OBS-023.

Sheet INPUT-Drift_Conditions
A1: Obs_ID | B1: Protocols | C1: Protocols | D1: Situasi Drift | E1: Drift_Level_1 | F1: Drift codes | G1: Drift_Level_2 | H1: Alasan / Penjelasan | I1: Observation_Sequence | J1: Observation_Status | K1: Active_Observation | L1: Improvement_ID
A2: OBS-001 | B2: WAH | C2: =IFERROR(VLOOKUP(B2,'DATABASE-DRIFT_LATENT_HP_ERROR'!$A$143:$B$160,2,FALSE()),"") -> Work at Height | D2: Pelaksanaan pemasangan dan pembongkaran scaffolding di lapangan lebih banyak mengandalkan pengalaman pekerja dibanding prosedur tertulis yang detail dan step-by-step. | E2: Skill-Based Performance Drift | F2: =IFERROR(VLOOKUP(E2,'DATABASE-DRIFT_LATENT_HP_ERROR'!$A$4:$B$13,2,FALSE()),"") -> Drift.3 | G2: Overreliance on experience | H2: =IFERROR(VLOOKUP(G2,'DATABASE-DRIFT_LATENT_HP_ERROR'!$B$16:$D$76,3,FALSE()),"") -> Pekerja lebih mengandalkan pengalaman dibanding prosedur atau engineering review. | I2: =IF($A2="","",IFERROR(INDEX('INPUT-SIF_Questions'!$B$2:$B$300,MATCH($A2,'INPUT-SIF_Questions'!$A$2:$A$300,0)),"")) -> 1 | J2: =IF($A2="","",IFERROR(INDEX('INPUT-SIF_Questions'!$F$2:$F$300,MATCH($A2,'INPUT-SIF_Questions'!$A$2:$A$300,0)),"")) -> Baseline | K2: =IF($A2="","",IFERROR(INDEX('INPUT-SIF_Questions'!$G$2:$G$300,MATCH($A2,'INPUT-SIF_Questions'!$A$2:$A$300,0)),"")) -> Y | L2: =IF($A2="","",IFERROR(INDEX('INPUT-SIF_Questions'!$E$2:$E$300,MATCH($A2,'INPUT-SIF_Questions'!$A$2:$A$300,0)),"")) -> 0
A3: OBS-001 | B3: WAH | C3: =IFERROR(VLOOKUP(B3,'DATABASE-DRIFT_LATENT_HP_ERROR'!$A$143:$B$160,2,FALSE()),"") -> Work at Height | D3: Urutan dismantling scaffolding, metode penurunan material, dan titik anchor belum dijelaskan secara spesifik sehingga terbuka terhadap berbagai interpretasi saat pekerjaan berlangsung. | E3: Procedural Drift | F3: =IFERROR(VLOOKUP(E3,'DATABASE-DRIFT_LATENT_HP_ERROR'!$A$4:$B$13,2,FALSE()),"") -> Drift.1 | G3: Procedure interpreted differently | H3: =IFERROR(VLOOKUP(G3,'DATABASE-DRIFT_LATENT_HP_ERROR'!$B$16:$D$76,3,FALSE()),"") -> Interpretasi prosedur berbeda antar personel atau departemen. | I3: =IF($A3="","",IFERROR(INDEX('INPUT-SIF_Questions'!$B$2:$B$300,MATCH($A3,'INPUT-SIF_Questions'!$A$2:$A$300,0)),"")) -> 1 | J3: =IF($A3="","",IFERROR(INDEX('INPUT-SIF_Questions'!$F$2:$F$300,MATCH($A3,'INPUT-SIF_Questions'!$A$2:$A$300,0)),"")) -> Baseline | K3: =IF($A3="","",IFERROR(INDEX('INPUT-SIF_Questions'!$G$2:$G$300,MATCH($A3,'INPUT-SIF_Questions'!$A$2:$A$300,0)),"")) -> Y | L3: =IF($A3="","",IFERROR(INDEX('INPUT-SIF_Questions'!$E$2:$E$300,MATCH($A3,'INPUT-SIF_Questions'!$A$2:$A$300,0)),"")) -> 0
A4: OBS-001 | B4: WAH | C4: =IFERROR(VLOOKUP(B4,'DATABASE-DRIFT_LATENT_HP_ERROR'!$A$143:$B$160,2,FALSE()),"") -> Work at Height | D4: Metode penurunan material scaffolding seperti standard, ledger, transom, bracing, base plate, sole board, dan coupler belum dijelaskan secara detail di dalam prosedur kerja. | E4: Procedural Drift | F4: =IFERROR(VLOOKUP(E4,'DATABASE-DRIFT_LATENT_HP_ERROR'!$A$4:$B$13,2,FALSE()),"") -> Drift.1 | G4: Procedure simplified | H4: =IFERROR(VLOOKUP(G4,'DATABASE-DRIFT_LATENT_HP_ERROR'!$B$16:$D$76,3,FALSE()),"") -> Procedure not detailed atau Prosedur kerja disederhanakan tanpa evaluasi risiko formal. | I4: =IF($A4="","",IFERROR(INDEX('INPUT-SIF_Questions'!$B$2:$B$300,MATCH($A4,'INPUT-SIF_Questions'!$A$2:$A$300,0)),"")) -> 1 | J4: =IF($A4="","",IFERROR(INDEX('INPUT-SIF_Questions'!$F$2:$F$300,MATCH($A4,'INPUT-SIF_Questions'!$A$2:$A$300,0)),"")) -> Baseline | K4: =IF($A4="","",IFERROR(INDEX('INPUT-SIF_Questions'!$G$2:$G$300,MATCH($A4,'INPUT-SIF_Questions'!$A$2:$A$300,0)),"")) -> Y | L4: =IF($A4="","",IFERROR(INDEX('INPUT-SIF_Questions'!$E$2:$E$300,MATCH($A4,'INPUT-SIF_Questions'!$A$2:$A$300,0)),"")) -> 0
A5: OBS-001 | B5: WAH | C5: =IFERROR(VLOOKUP(B5,'DATABASE-DRIFT_LATENT_HP_ERROR'!$A$143:$B$160,2,FALSE()),"") -> Work at Height | D5: Beberapa pekerja belum secara konsisten mengikat tool seperti kunci ratchet untuk mencegah dropped object hazard. | E5: Barrier Management Drift | F5: =IFERROR(VLOOKUP(E5,'DATABASE-DRIFT_LATENT_HP_ERROR'!$A$4:$B$13,2,FALSE()),"") -> Drift.5 | G5: Barrier verification ineffective | H5: =IFERROR(VLOOKUP(G5,'DATABASE-DRIFT_LATENT_HP_ERROR'!$B$16:$D$76,3,FALSE()),"") -> Proses verifikasi safeguard tidak mampu mendeteksi kelemahan barrier. | I5: =IF($A5="","",IFERROR(INDEX('INPUT-SIF_Questions'!$B$2:$B$300,MATCH($A5,'INPUT-SIF_Questions'!$A$2:$A$300,0)),"")) -> 1 | J5: =IF($A5="","",IFERROR(INDEX('INPUT-SIF_Questions'!$F$2:$F$300,MATCH($A5,'INPUT-SIF_Questions'!$A$2:$A$300,0)),"")) -> Baseline | K5: =IF($A5="","",IFERROR(INDEX('INPUT-SIF_Questions'!$G$2:$G$300,MATCH($A5,'INPUT-SIF_Questions'!$A$2:$A$300,0)),"")) -> Y | L5: =IF($A5="","",IFERROR(INDEX('INPUT-SIF_Questions'!$E$2:$E$300,MATCH($A5,'INPUT-SIF_Questions'!$A$2:$A$300,0)),"")) -> 0
A6: OBS-001 | B6: WAH | C6: =IFERROR(VLOOKUP(B6,'DATABASE-DRIFT_LATENT_HP_ERROR'!$A$143:$B$160,2,FALSE()),"") -> Work at Height | D6: Aktivitas dismantling scaffolding lebih banyak dilakukan dalam skill-based performance mode karena tingginya pengalaman kerja personel sehingga pekerja lebih mengandalkan kebiasaan dan pengalaman dibanding disiplin terhadap prosedur kerja berbasis rule-based performance. | E6: Skill-Based Performance Drift | F6: =IFERROR(VLOOKUP(E6,'DATABASE-DRIFT_LATENT_HP_ERROR'!$A$4:$B$13,2,FALSE()),"") -> Drift.3 | G6: Familiarity-driven shortcut | H6: =IFERROR(VLOOKUP(G6,'DATABASE-DRIFT_LATENT_HP_ERROR'!$B$16:$D$76,3,FALSE()),"") -> Kedekatan/familiaritas terhadap pekerjaan memicu pengurangan safeguard. | I6: =IF($A6="","",IFERROR(INDEX('INPUT-SIF_Questions'!$B$2:$B$300,MATCH($A6,'INPUT-SIF_Questions'!$A$2:$A$300,0)),"")) -> 1 | J6: =IF($A6="","",IFERROR(INDEX('INPUT-SIF_Questions'!$F$2:$F$300,MATCH($A6,'INPUT-SIF_Questions'!$A$2:$A$300,0)),"")) -> Baseline | K6: =IF($A6="","",IFERROR(INDEX('INPUT-SIF_Questions'!$G$2:$G$300,MATCH($A6,'INPUT-SIF_Questions'!$A$2:$A$300,0)),"")) -> Y | L6: =IF($A6="","",IFERROR(INDEX('INPUT-SIF_Questions'!$E$2:$E$300,MATCH($A6,'INPUT-SIF_Questions'!$A$2:$A$300,0)),"")) -> 0
A7: OBS-001 | B7: WAH | C7: =IFERROR(VLOOKUP(B7,'DATABASE-DRIFT_LATENT_HP_ERROR'!$A$143:$B$160,2,FALSE()),"") -> Work at Height | D7: Penggunaan fall arrest system telah menjadi praktik yang dianggap normal tanpa evaluasi memadai terhadap hierarchy of control Work at Height, dimana fall prevention dan fall restraint seharusnya menjadi prioritas utama sebelum penggunaan fall arrest sebagai mitigasi terakhir. | E7: Risk Assessment Drift | F7: =IFERROR(VLOOKUP(E7,'DATABASE-DRIFT_LATENT_HP_ERROR'!$A$4:$B$13,2,FALSE()),"") -> Drift.7 | G7: Hazard underestimated | H7: =IFERROR(VLOOKUP(G7,'DATABASE-DRIFT_LATENT_HP_ERROR'!$B$16:$D$76,3,FALSE()),"") -> Tingkat risiko diremehkan dibanding exposure aktual. | I7: =IF($A7="","",IFERROR(INDEX('INPUT-SIF_Questions'!$B$2:$B$300,MATCH($A7,'INPUT-SIF_Questions'!$A$2:$A$300,0)),"")) -> 1 | J7: =IF($A7="","",IFERROR(INDEX('INPUT-SIF_Questions'!$F$2:$F$300,MATCH($A7,'INPUT-SIF_Questions'!$A$2:$A$300,0)),"")) -> Baseline | K7: =IF($A7="","",IFERROR(INDEX('INPUT-SIF_Questions'!$G$2:$G$300,MATCH($A7,'INPUT-SIF_Questions'!$A$2:$A$300,0)),"")) -> Y | L7: =IF($A7="","",IFERROR(INDEX('INPUT-SIF_Questions'!$E$2:$E$300,MATCH($A7,'INPUT-SIF_Questions'!$A$2:$A$300,0)),"")) -> 0
A8: OBS-001 | B8: WAH | C8: =IFERROR(VLOOKUP(B8,'DATABASE-DRIFT_LATENT_HP_ERROR'!$A$143:$B$160,2,FALSE()),"") -> Work at Height | D8: Free fall distance, swing fall hazard, jalur jatuh, serta potensi benturan terhadap struktur atau benda lain belum secara konsisten diperhitungkan dalam pekerjaan WAH. | E8: Risk Assessment Drift | F8: =IFERROR(VLOOKUP(E8,'DATABASE-DRIFT_LATENT_HP_ERROR'!$A$4:$B$13,2,FALSE()),"") -> Drift.7 | G8: Engineering risk not evaluated | H8: =IFERROR(VLOOKUP(G8,'DATABASE-DRIFT_LATENT_HP_ERROR'!$B$16:$D$76,3,FALSE()),"") -> Risiko engineering tidak dianalisa secara teknikal. | I8: =IF($A8="","",IFERROR(INDEX('INPUT-SIF_Questions'!$B$2:$B$300,MATCH($A8,'INPUT-SIF_Questions'!$A$2:$A$300,0)),"")) -> 1 | J8: =IF($A8="","",IFERROR(INDEX('INPUT-SIF_Questions'!$F$2:$F$300,MATCH($A8,'INPUT-SIF_Questions'!$A$2:$A$300,0)),"")) -> Baseline | K8: =IF($A8="","",IFERROR(INDEX('INPUT-SIF_Questions'!$G$2:$G$300,MATCH($A8,'INPUT-SIF_Questions'!$A$2:$A$300,0)),"")) -> Y | L8: =IF($A8="","",IFERROR(INDEX('INPUT-SIF_Questions'!$E$2:$E$300,MATCH($A8,'INPUT-SIF_Questions'!$A$2:$A$300,0)),"")) -> 0
A9: OBS-001 | B9: WAH | C9: =IFERROR(VLOOKUP(B9,'DATABASE-DRIFT_LATENT_HP_ERROR'!$A$143:$B$160,2,FALSE()),"") -> Work at Height | D9: Penggunaan harness lebih dipandang sebagai compliance penggunaan APD dibanding engineering safeguard terhadap bahaya jatuh. | E9: Administrative Compliance Drift | F9: =IFERROR(VLOOKUP(E9,'DATABASE-DRIFT_LATENT_HP_ERROR'!$A$4:$B$13,2,FALSE()),"") -> Drift.4 | G9: Checklist mentality | H9: =IFERROR(VLOOKUP(G9,'DATABASE-DRIFT_LATENT_HP_ERROR'!$B$16:$D$76,3,FALSE()),"") -> Checklist hanya diparaf sebagai formalitas administratif. | I9: =IF($A9="","",IFERROR(INDEX('INPUT-SIF_Questions'!$B$2:$B$300,MATCH($A9,'INPUT-SIF_Questions'!$A$2:$A$300,0)),"")) -> 1 | J9: =IF($A9="","",IFERROR(INDEX('INPUT-SIF_Questions'!$F$2:$F$300,MATCH($A9,'INPUT-SIF_Questions'!$A$2:$A$300,0)),"")) -> Baseline | K9: =IF($A9="","",IFERROR(INDEX('INPUT-SIF_Questions'!$G$2:$G$300,MATCH($A9,'INPUT-SIF_Questions'!$A$2:$A$300,0)),"")) -> Y | L9: =IF($A9="","",IFERROR(INDEX('INPUT-SIF_Questions'!$E$2:$E$300,MATCH($A9,'INPUT-SIF_Questions'!$A$2:$A$300,0)),"")) -> 0
A10: OBS-001 | B10: WAH | C10: =IFERROR(VLOOKUP(B10,'DATABASE-DRIFT_LATENT_HP_ERROR'!$A$143:$B$160,2,FALSE()),"") -> Work at Height | D10: SWC dan checklist pekerjaan cenderung diperlakukan sebagai formalitas administratif, dengan asumsi bahwa pekerja telah memahami seluruh requirement teknikal secara otomatis tanpa diskusi mendalam mengenai critical safeguards dan engineering consequence pada pekerjaan WAH. | E10: Administrative Compliance Drift | F10: =IFERROR(VLOOKUP(E10,'DATABASE-DRIFT_LATENT_HP_ERROR'!$A$4:$B$13,2,FALSE()),"") -> Drift.4 | G10: SWC treated as formality | H10: =IFERROR(VLOOKUP(G10,'DATABASE-DRIFT_LATENT_HP_ERROR'!$B$16:$D$76,3,FALSE()),"") -> SWC tidak digunakan sebagai critical thinking tool. | I10: =IF($A10="","",IFERROR(INDEX('INPUT-SIF_Questions'!$B$2:$B$300,MATCH($A10,'INPUT-SIF_Questions'!$A$2:$A$300,0)),"")) -> 1 | J10: =IF($A10="","",IFERROR(INDEX('INPUT-SIF_Questions'!$F$2:$F$300,MATCH($A10,'INPUT-SIF_Questions'!$A$2:$A$300,0)),"")) -> Baseline | K10: =IF($A10="","",IFERROR(INDEX('INPUT-SIF_Questions'!$G$2:$G$300,MATCH($A10,'INPUT-SIF_Questions'!$A$2:$A$300,0)),"")) -> Y | L10: =IF($A10="","",IFERROR(INDEX('INPUT-SIF_Questions'!$E$2:$E$300,MATCH($A10,'INPUT-SIF_Questions'!$A$2:$A$300,0)),"")) -> 0
